Workbook

Sheet 給料
A1: 年 | B1: 月 | C1: 総手取り | D1: 給料手取り | E1: ボーナス手取り | F1: 給料 | G1: 雇用保険対象額 | H1: 課税対象額 | I1: 基本給 | J1: 時間外手当 | K1: 通勤費 | L1: 裁量労働手当 | M1: 在宅勤務費用補填 | N1: その他 | O1: その他 | P1: その他 | Q1: 謎課税 | R1: 控除 | S1: 雇用保険料 | T1: 厚生年金保険料 | U1: 健康保険(基本) | V1: 健康保険(特定) | W1: 子ども・子育て支援金 | X1: 所得税 | Y1: 住民税 | Z1: 労働組合費 | AA1: 共済会費 | AB1: 損害保険料 | AC1: 昼飯 | AD1: 家賃 | AE1: その他控除 | AF1: ボーナス | AG1: 基本賞与 | AH1: 個人別業績賞与 | AI1: その他手当 | AJ1: ボーナス控除 | AK1: 雇用保険料 | AL1: 厚生年金保険料 | AM1: 健康保険(基本) | AN1: 健康保険(特定) | AP1: 所得税 | AQ1: 年収 | AR1: 前年増減 | AS1: 前年増減月割り | AT1: 年手取り | AU1: 年手取り前年増減 | AV1: 年手取り前年増減月割り
A2: 2015 | B2: 4 | C2: =D2+E2 -> 212684 | D2: =F2-R2 -> 212684 | F2: =SUM(I2:P2) -> 233000 | G2: =SUM(I2:O2)-N2-M2 -> 233000 | H2: =SUM(I2:O2)-SUM(K2:K2)+Q2 -> 233000 | I2: 233000 | J2: 0 | K2: 0 | L2: 0 | M2: 0 | N2: 0 | O2: 0 | P2: 0 | Q2: 0 | R2: =SUM(S2:AE2) -> 20316 | S2: =FLOOR((G2)*IF(B2<=3,VLOOKUP(A2-1,割合!A:B,2,FALSE),VLOOKUP(A2,割合!A:B,2,FALSE)),1) -> 1165 | T2: 0 | U2: 0 | V2: 0 | W2: 0 | X2: 5900 | Y2: 0 | Z2: 2190 | AA2: 0 | AB2: 0 | AC2: 0 | AD2: 10700 | AE2: 361
A3: 2015 | B3: 5 | C3: =D3+E3 -> 184848 | D3: =F3-R3 -> 184848 | F3: =SUM(I3:P3) -> 233000 | G3: =SUM(I3:O3)-N3-M3 -> 233000 | H3: =SUM(I3:O3)-SUM(K3:K3)+Q3 -> 233000 | I3: =I2 -> 233000 | J3: 0 | K3: 0 | L3: 0 | M3: 0 | N3: 0 | O3: 0 | P3: 0 | Q3: 0 | R3: =SUM(S3:AE3) -> 48152 | S3: =FLOOR((G3)*IF(B3<=3,VLOOKUP(A3-1,割合!A:B,2,FALSE),VLOOKUP(A3,割合!A:B,2,FALSE)),1) -> 1165 | T3: 20968 | U3: 5298 | V3: 3870 | W3: 0 | X3: 4820 | Y3: =Y2 -> 0 | Z3: =Z2 -> 2190 | AA3: 100 | AB3: =AB2 -> 0 | AC3: 0 | AD3: =AD2 -> 10700 | AE3: =-10200+9241 -> -959
A4: 2015 | B4: 6 | C4: =D4+E4 -> 282154 | D4: =F4-R4 -> 177913 | E4: =AF4-AJ4 -> 104241 | F4: =SUM(I4:P4) -> 233000 | G4: =SUM(I4:O4)-N4-M4 -> 233000 | H4: =SUM(I4:O4)-SUM(K4:K4)+Q4 -> 233000 | I4: =I3 -> 233000 | J4: 0 | K4: 0 | L4: 0 | M4: 0 | N4: 0 | O4: 0 | P4: 0 | Q4: 0 | R4: =SUM(S4:AE4) -> 55087 | S4: =FLOOR((G4)*IF(B4<=3,VLOOKUP(A4-1,割合!A:B,2,FALSE),VLOOKUP(A4,割合!A:B,2,FALSE)),1) -> 1165 | T4: =T3 -> 20968 | U4: =U3 -> 5298 | V4: =V3 -> 3870 | W4: 0 | X4: 4820 | Y4: =Y3 -> 0 | Z4: =Z3 -> 2190 | AA4: =AA3 -> 100 | AB4: 1350 | AC4: 606 | AD4: =AD3 -> 10700 | AE4: =4020 -> 4020 | AF4: =SUM(AG4:AI4) -> 125000 | AG4: 125000 | AH4: 0 | AI4: 0 | AJ4: =SUM(AK4:AP4) -> 20759 | AK4: =FLOOR(AF4*VLOOKUP(A4,割合!A:B,2,FALSE),1) -> 625 | AL4: 10921 | AM4: 2760 | AN4: 2015 | AO4: 0 | AP4: 4438
A5: 2015 | B5: 7 | C5: =D5+E5 -> 198498 | D5: =F5-R5 -> 198498 | F5: =SUM(I5:P5) -> 242731 | G5: =SUM(I5:O5)-N5-M5 -> 242731 | H5: =SUM(I5:O5)-SUM(K5:K5)+Q5 -> 242731 | I5: =I4 -> 233000 | J5: 9731 | K5: 0 | L5: 0 | M5: 0 | N5: 0 | O5: 0 | P5: 0 | Q5: 0 | R5: =SUM(S5:AE5) -> 44233 | S5: =FLOOR((G5)*IF(B5<=3,VLOOKUP(A5-1,割合!A:B,2,FALSE),VLOOKUP(A5,割合!A:B,2,FALSE)),1) -> 1213 | T5: =T4 -> 20968 | U5: =U4 -> 5298 | V5: =V4 -> 3870 | W5: 0 | X5: 5170 | Y5: =Y4 -> 0 | Z5: =Z4 -> 2190 | AA5: =AA4 -> 100 | AB5: =AB4 -> 1350 | AC5: 0 | AD5: 0 | AE5: =4074 -> 4074
A6: 2015 | B6: 8 | C6: =D6+E6 -> 130530 | D6: =F6-R6 -> 130530 | F6: =SUM(I6:P6) -> 259680 | G6: =SUM(I6:O6)-N6-M6 -> 259680 | H6: =SUM(I6:O6)-SUM(K6:K6)+Q6 -> 233000 | I6: =I5 -> 233000 | J6: 0 | K6: 26680 | L6: 0 | M6: 0 | N6: 0 | O6: 0 | P6: 0 | Q6: 0 | R6: =SUM(S6:AE6) -> 129150 | S6: =FLOOR((G6)*IF(B6<=3,VLOOKUP(A6-1,割合!A:B,2,FALSE),VLOOKUP(A6,割合!A:B,2,FALSE)),1) -> 1298 | T6: =T5 -> 20968 | U6: =U5 -> 5298 | V6: =V5 -> 3870 | W6: 0 | X6: 4820 | Y6: =Y5 -> 0 | Z6: =Z5 -> 2190 | AA6: =AA5 -> 100 | AB6: =AB5 -> 1350 | AC6: 0 | AD6: 28670 | AE6: =28186+32400 -> 60586
A7: 2015 | B7: 9 | C7: =D7+E7 -> 164569 | D7: =F7-R7 -> 164569 | F7: =SUM(I7:P7) -> 233000 | G7: =SUM(I7:O7)-N7-M7 -> 233000 | H7: =SUM(I7:O7)-SUM(K7:K7)+Q7 -> 233000 | I7: =I6 -> 233000 | J7: 0 | K7: 0 | L7: 0 | M7: 0 | N7: 0 | O7: 0 | P7: 0 | Q7: 0 | R7: =SUM(S7:AE7) -> 68431 | S7: =FLOOR((G7)*IF(B7<=3,VLOOKUP(A7-1,割合!A:B,2,FALSE),VLOOKUP(A7,割合!A:B,2,FALSE)),1) -> 1165 | T7: =T6 -> 20968 | U7: =U6 -> 5298 | V7: =V6 -> 3870 | W7: 0 | X7: 4820 | Y7: =Y6 -> 0 | Z7: =Z6 -> 2190 | AA7: =AA6 -> 100 | AB7: =AB6 -> 1350 | AC7: 0 | AD7: =AD6 -> 28670 | AE7: 0
A8: 2015 | B8: 10 | C8: =D8+E8 -> 167827 | D8: =F8-R8 -> 167827 | F8: =SUM(I8:P8) -> 237555 | G8: =SUM(I8:O8)-N8-M8 -> 237555 | H8: =SUM(I8:O8)-SUM(K8:K8)+Q8 -> 237555 | I8: =I7 -> 233000 | J8: 4555 | K8: 0 | L8: 0 | M8: 0 | N8: 0 | O8: 0 | P8: 0 | Q8: 0 | R8: =SUM(S8:AE8) -> 69728 | S8: =FLOOR((G8)*IF(B8<=3,VLOOKUP(A8-1,割合!A:B,2,FALSE),VLOOKUP(A8,割合!A:B,2,FALSE)),1) -> 1187 | T8: 21393 | U8: =U7 -> 5298 | V8: =V7 -> 3870 | W8: 0 | X8: 4970 | Y8: =Y7 -> 0 | Z8: 2890 | AA8: =AA7 -> 100 | AB8: =AB7 -> 1350 | AC8: 0 | AD8: =AD7 -> 28670 | AE8: 0
A9: 2015 | B9: 11 | C9: =D9+E9 -> 170312 | D9: =F9-R9 -> 170312 | F9: =SUM(I9:P9) -> 240143 | G9: =SUM(I9:O9)-N9-M9 -> 240143 | H9: =SUM(I9:O9)-SUM(K9:K9)+Q9 -> 240143 | I9: =I8 -> 233000 | J9: 7143 | K9: 0 | L9: 0 | M9: 0 | N9: 0 | O9: 0 | P9: 0 | Q9: 0 | R9: =SUM(S9:AE9) -> 69831 | S9: =FLOOR((G9)*IF(B9<=3,VLOOKUP(A9-1,割合!A:B,2,FALSE),VLOOKUP(A9,割合!A:B,2,FALSE)),1) -> 1200 | T9: =T8 -> 21393 | U9: =U8 -> 5298 | V9: =V8 -> 3870 | W9: 0 | X9: 5060 | Y9: =Y8 -> 0 | Z9: =Z8 -> 2890 | AA9: =AA8 -> 100 | AB9: =AB8 -> 1350 | AC9: 0 | AD9: =AD8 -> 28670 | AE9: 0
A10: 2015 | B10: 12 | C10: =D10+E10 -> 707563 | D10: =F10-R10 -> 314752 | E10: =AF10-AJ10 -> 392811 | F10: =SUM(I10:P10) -> 384301 | G10: =SUM(I10:O10)-N10-M10 -> 384301 | H10: =SUM(I10:O10)-SUM(K10:K10)+Q10 -> 384301 | I10: =I9 -> 233000 | J10: 151301 | K10: 0 | L10: 0 | M10: 0 | N10: 0 | O10: 0 | P10: 0 | Q10: 0 | R10: =SUM(S10:AE10) -> 69549 | S10: =FLOOR((G10)*IF(B10<=3,VLOOKUP(A10-1,割合!A:B,2,FALSE),VLOOKUP(A10,割合!A:B,2,FALSE)),1) -> 1921 | T10: =T9 -> 21393 | U10: =U9 -> 5298 | V10: =V9 -> 3870 | W10: 0 | X10: 4057 | Y10: =Y9 -> 0 | Z10: =Z9 -> 2890 | AA10: =AA9 -> 100 | AB10: =AB9 -> 1350 | AC10: 0 | AD10: =AD9 -> 28670 | AE10: 0 | AF10: =SUM(AG10:AI10) -> 472000 | AG10: 250000 | AH10: 182000 | AI10: 40000 | AJ10: =SUM(AK10:AP10) -> 79189 | AK10: =FLOOR(AF10*VLOOKUP(A10,割合!A:B,2,FALSE),1) -> 2360 | AL10: 42074 | AM10: 10419 | AN10: 7611 | AO10: 0 | AP10: 16725 | AQ10: =SUM(H2:H10)+SUM(AF2:AF10)+251628 -> 3118358 | AT10: =SUM(C2:C10)+SUM(AC2:AE10) -> 2463123 | AW10: =AT10/AQ10 -> 0.7898782
A11: 2016 | B11: 1 | C11: =D11+E11 -> 227579 | D11: =F11-R11 -> 227579 | F11: =SUM(I11:P11) -> 300070 | G11: =SUM(I11:O11)-N11-M11 -> 300070 | H11: =SUM(I11:O11)-SUM(K11:K11)+Q11 -> 300070 | I11: =I10 -> 233000 | J11: 67070 | K11: 0 | L11: 0 | M11: 0 | N11: 0 | O11: 0 | P11: 0 | Q11: 0 | R11: =SUM(S11:AE11) -> 72491 | S11: =FLOOR((G11)*IF(B11<=3,VLOOKUP(A11-1,割合!A:B,2,FALSE),VLOOKUP(A11,割合!A:B,2,FALSE)),1) -> 1500 | T11: =T10 -> 21393 | U11: =U10 -> 5298 | V11: =V10 -> 3870 | W11: 0 | X11: 7190 | Y11: =Y10 -> 0 | Z11: =Z10 -> 2890 | AA11: =AA10 -> 100 | AB11: 1580 | AC11: 0 | AD11: =AD10 -> 28670 | AE11: 0
A12: 2016 | B12: 2 | C12: =D12+E12 -> 315240 | D12: =F12-R12 -> 315240 | F12: =SUM(I12:P12) -> 392061 | G12: =SUM(I12:O12)-N12-M12 -> 392061 | H12: =SUM(I12:O12)-SUM(K12:K12)+Q12 -> 365381 | I12: =I11 -> 233000 | J12: 132381 | K12: 26680 | L12: 0 | M12: 0 | N12: 0 | O12: 0 | P12: 0 | Q12: 0 | R12: =SUM(S12:AE12) -> 76821 | S12: =FLOOR((G12)*IF(B12<=3,VLOOKUP(A12-1,割合!A:B,2,FALSE),VLOOKUP(A12,割合!A:B,2,FALSE)),1) -> 1960 | T12: =T11 -> 21393 | U12: =U11 -> 5298 | V12: =V11 -> 3870 | W12: 0 | X12: 11060 | Y12: =Y11 -> 0 | Z12: =Z11 -> 2890 | AA12: =AA11 -> 100 | AB12: =AB11 -> 1580 | AC12: 0 | AD12: =AD11 -> 28670 | AE12: 0
A13: 2016 | B13: 3 | C13: =D13+E13 -> 306070 | D13: =F13-R13 -> 306070 | F13: =SUM(I13:P13) -> 384413 | G13: =SUM(I13:O13)-N13-M13 -> 384413 | H13: =SUM(I13:O13)-SUM(K13:K13)+Q13 -> 384413 | I13: =I12 -> 233000 | J13: 151413 | K13: 0 | L13: 0 | M13: 0 | N13: 0 | O13: 0 | P13: 0 | Q13: 0 | R13: =SUM(S13:AE13) -> 78343 | S13: =FLOOR((G13)*IF(B13<=3,VLOOKUP(A13-1,割合!A:B,2,FALSE),VLOOKUP(A13,割合!A:B,2,FALSE)),1) -> 1922 | T13: =T12 -> 21393 | U13: =U12 -> 5298 | V13: =V12 -> 3870 | W13: 0 | X13: 12620 | Y13: =Y12 -> 0 | Z13: =Z12 -> 2890 | AA13: =AA12 -> 100 | AB13: =AB12 -> 1580 | AC13: 0 | AD13: =AD12 -> 28670 | AE13: 0
A14: 2016 | B14: 4 | C14: =D14+E14 -> 255592 | D14: =F14-R14 -> 255592 | F14: =SUM(I14:P14) -> 329039 | G14: =SUM(I14:O14)-N14-M14 -> 329039 | H14: =SUM(I14:O14)-SUM(K14:K14)+Q14 -> 329039 | I14: 240000 | J14: 89039 | K14: 0 | L14: 0 | M14: 0 | N14: 0 | O14: 0 | P14: 0 | Q14: 0 | R14: =SUM(S14:AE14) -> 73447 | S14: =FLOOR((G14)*IF(B14<=3,VLOOKUP(A14-1,割合!A:B,2,FALSE),VLOOKUP(A14,割合!A:B,2,FALSE)),1) -> 1316 | T14: =T13 -> 21393 | U14: =U13 -> 5298 | V14: =V13 -> 3870 | W14: 0 | X14: 8240 | Y14: =Y13 -> 0 | Z14: 2980 | AA14: =AA13 -> 100 | AB14: =AB13 -> 1580 | AC14: 0 | AD14: =AD13 -> 28670 | AE14: 0
A15: 2016 | B15: 5 | C15: =D15+E15 -> 245985 | D15: =F15-R15 -> 245985 | F15: =SUM(I15:P15) -> 319032 | G15: =SUM(I15:O15)-N15-M15 -> 319032 | H15: =SUM(I15:O15)-SUM(K15:K15)+Q15 -> 319032 | I15: =I14 -> 240000 | J15: 79032 | K15: 0 | L15: 0 | M15: 0 | N15: 0 | O15: 0 | P15: 0 | Q15: 0 | R15: =SUM(S15:AE15) -> 73047 | S15: =FLOOR((G15)*IF(B15<=3,VLOOKUP(A15-1,割合!A:B,2,FALSE),VLOOKUP(A15,割合!A:B,2,FALSE)),1) -> 1276 | T15: =T14 -> 21393 | U15: 5286 | V15: 3882 | W15: 0 | X15: 7880 | Y15: =Y14 -> 0 | Z15: =Z14 -> 2980 | AA15: =AA14 -> 100 | AB15: =AB14 -> 1580 | AC15: 0 | AD15: =AD14 -> 28670 | AE15: 0
A16: 2016 | B16: 6 | C16: =D16+E16 -> 633238 | D16: =F16-R16 -> 230406 | E16: =AF16-AJ16 -> 402832 | F16: =SUM(I16:P16) -> 315408 | G16: =SUM(I16:O16)-N16-M16 -> 315408 | H16: =SUM(I16:O16)-SUM(K16:K16)+Q16 -> 315408 | I16: =I15 -> 240000 | J16: 75408 | K16: 0 | L16: 0 | M16: 0 | N16: 0 | O16: 0 | P16: 0 | Q16: 0 | R16: =SUM(S16:AE16) -> 85002 | S16: =FLOOR((G16)*IF(B16<=3,VLOOKUP(A16-1,割合!A:B,2,FALSE),VLOOKUP(A16,割合!A:B,2,FALSE)),1) -> 1261 | T16: =T15 -> 21393 | U16: =U15 -> 5286 | V16: =V15 -> 3882 | W16: 0 | X16: 7750 | Y16: 12100 | Z16: =Z15 -> 2980 | AA16: =AA15 -> 100 | AB16: =AB15 -> 1580 | AC16: 0 | AD16: =AD15 -> 28670 | AE16: 0 | AF16: =SUM(AG16:AI16) -> 494000 | AG16: 250000 | AH16: 244000 | AI16: 0 | AJ16: =SUM(AK16:AP16) -> 91168 | AK16: =FLOOR(AF16*VLOOKUP(A16,割合!A:B,2,FALSE),1) -> 1976 | AL16: 44035 | AM16: 10879 | AN16: 7991 | AO16: 0 | AP16: 26287
A17: 2016 | B17: 7 | C17: =D17+E17 -> 230209 | D17: =F17-R17 -> 230209 | F17: =SUM(I17:P17) -> 314367 | G17: =SUM(I17:O17)-N17-M17 -> 314367 | H17: =SUM(I17:O17)-SUM(K17:K17)+Q17 -> 314367 | I17: =I16 -> 240000 | J17: 74367 | K17: 0 | L17: 0 | M17: 0 | N17: 0 | O17: 0 | P17: 0 | Q17: 0 | R17: =SUM(S17:AE17) -> 84158 | S17: =FLOOR((G17)*IF(B17<=3,VLOOKUP(A17-1,割合!A:B,2,FALSE),VLOOKUP(A17,割合!A:B,2,FALSE)),1) -> 1257 | T17: =T16 -> 21393 | U17: =U16 -> 5286 | V17: =V16 -> 3882 | W17: 0 | X17: 7710 | Y17: 11300 | Z17: =Z16 -> 2980 | AA17: =AA16 -> 100 | AB17: =AB16 -> 1580 | AC17: 0 | AD17: =AD16 -> 28670 | AE17: 0
A18: 2016 | B18: 8 | C18: =D18+E18 -> 253900 | D18: =F18-R18 -> 253900 | F18: =SUM(I18:P18) -> 348391 | G18: =SUM(I18:O18)-N18-M18 -> 348391 | H18: =SUM(I18:O18)-SUM(K18:K18)+Q18 -> 321711 | I18: =I17 -> 240000 | J18: 81711 | K18: 26680 | L18: 0 | M18: 0 | N18: 0 | O18: 0 | P18: 0 | Q18: 0 | R18: =SUM(S18:AE18) -> 94491 | S18: =FLOOR((G18)*IF(B18<=3,VLOOKUP(A18-1,割合!A:B,2,FALSE),VLOOKUP(A18,割合!A:B,2,FALSE)),1) -> 1393 | T18: 28524 | U18: 7048 | V18: 5176 | W18: 0 | X18: 7720 | Y18: =Y17 -> 11300 | Z18: =Z17 -> 2980 | AA18: =AA17 -> 100 | AB18: =AB17 -> 1580 | AC18: 0 | AD18: =AD17 -> 28670 | AE18: 0
A19: 2016 | B19: 9 | C19: =D19+E19 -> 272969 | D19: =F19-R19 -> 272969 | F19: =SUM(I19:P19) -> 370519 | G19: =SUM(I19:O19)-N19-M19 -> 370519 | H19: =SUM(I19:O19)-SUM(K19:K19)+Q19 -> 370519 | I19: =I18 -> 240000 | J19: 130519 | K19: 0 | L19: 0 | M19: 0 | N19: 0 | O19: 0 | P19: 0 | Q19: 0 | R19: =SUM(S19:AE19) -> 97550 | S19: =FLOOR((G19)*IF(B19<=3,VLOOKUP(A19-1,割合!A:B,2,FALSE),VLOOKUP(A19,割合!A:B,2,FALSE)),1) -> 1482 | T19: =T18 -> 28524 | U19: =U18 -> 7048 | V19: =V18 -> 5176 | W19: 0 | X19: 10690 | Y19: =Y18 -> 11300 | Z19: =Z18 -> 2980 | AA19: =AA18 -> 100 | AB19: =AB18 -> 1580 | AC19: 0 | AD19: =AD18 -> 28670 | AE19: 0
A20: 2016 | B20: 10 | C20: =D20+E20 -> 461559 | D20: =F20-R20 -> 461559 | F20: =SUM(I20:P20) -> 559411 | G20: =SUM(I20:O20)-N20-M20 -> 559411 | H20: =SUM(I20:O20)-SUM(K20:K20)+Q20 -> 359281 | I20: =I19 -> 240000 | J20: 119281 | K20: 200130 | L20: 0 | M20: 0 | N20: 0 | O20: 0 | P20: 0 | Q20: 0 | R20: =SUM(S20:AE20) -> 97852 | S20: =FLOOR((G20)*IF(B20<=3,VLOOKUP(A20-1,割合!A:B,2,FALSE),VLOOKUP(A20,割合!A:B,2,FALSE)),1) -> 2237 | T20: 29091 | U20: =U19 -> 7048 | V20: =V19 -> 5176 | W20: 0 | X20: 9670 | Y20: =Y19 -> 11300 | Z20: =Z19 -> 2980 | AA20: =AA19 -> 100 | AB20: =AB19 -> 1580 | AC20: 0 | AD20: =AD19 -> 28670 | AE20: 0
A21: 2016 | B21: 11 | C21: =D21+E21 -> 329183 | D21: =F21-R21 -> 329183 | F21: =SUM(I21:P21) -> 432508 | G21: =SUM(I21:O21)-N21-M21 -> 422508 | H21: =SUM(I21:O21)-SUM(K21:K21)+Q21 -> 432508 | I21: =I20 -> 240000 | J21: 182508 | K21: 0 | L21: 0 | M21: 0 | N21: 10000 | O21: 0 | P21: 0 | Q21: 0 | R21: =SUM(S21:AE21) -> 103325 | S21: =FLOOR((G21)*IF(B21<=3,VLOOKUP(A21-1,割合!A:B,2,FALSE),VLOOKUP(A21,割合!A:B,2,FALSE)),1) -> 1690 | T21: =T20 -> 29091 | U21: =U20 -> 7048 | V21: =V20 -> 5176 | W21: 0 | X21: 15690 | Y21: =Y20 -> 11300 | Z21: =Z20 -> 2980 | AA21: =AA20 -> 100 | AB21: =AB20 -> 1580 | AC21: 0 | AD21: =AD20 -> 28670 | AE21: 0
A22: 2016 | B22: 12 | C22: =D22+E22 -> 620292 | D22: =F22-R22 -> 250601 | E22: =AF22-AJ22 -> 369691 | F22: =SUM(I22:P22) -> 317490 | G22: =SUM(I22:O22)-N22-M22 -> 317490 | H22: =SUM(I22:O22)-SUM(K22:K22)+Q22 -> 317490 | I22: =I21 -> 240000 | J22: 77490 | K22: 0 | L22: 0 | M22: 0 | N22: 0 | O22: 0 | P22: 0 | Q22: 0 | R22: =SUM(S22:AE22) -> 66889 | S22: =FLOOR((G22)*IF(B22<=3,VLOOKUP(A22-1,割合!A:B,2,FALSE),VLOOKUP(A22,割合!A:B,2,FALSE)),1) -> 1269 | T22: =T21 -> 29091 | U22: =U21 -> 7048 | V22: =V21 -> 5176 | W22: 0 | X22: -20325 | Y22: =Y21 -> 11300 | Z22: =Z21 -> 2980 | AA22: =AA21 -> 100 | AB22: =AB21 -> 1580 | AC22: 0 | AD22: =AD21 -> 28670 | AE22: 0 | AF22: =SUM(AG22:AI22) -> 486000 | AG22: 250000 | AH22: 236000 | AI22: 0 | AJ22: =SUM(AK22:AP22) -> 116309 | AK22: =FLOOR(AF22*VLOOKUP(A22,割合!A:B,2,FALSE),1) -> 1944 | AL22: 44182 | AM22: 10703 | AN22: 7862 | AO22: 0 | AP22: 51618 | AQ22: =SUM(H11:H22)+SUM(AF11:AF22) -> 5109219 | AR22: =AQ22-AQ10 -> 1990861 | AS22: =AR22/12 -> 165905.08 | AT22: =SUM(C11:C22)+SUM(AC11:AE22) -> 4495856 | AU22: =AT22-AT10 -> 2032733 | AV22: =AU22/12 -> 169394.42 | AW22: =AT22/AQ22 -> 0.87994975
A23: =A11+1 -> 2017 | B23: =B11 -> 1 | C23: =D23+E23 -> 212426 | D23: =F23-R23 -> 212426 | F23: =SUM(I23:P23) -> 306657 | G23: =SUM(I23:O23)-N23-M23 -> 306657 | H23: =SUM(I23:O23)-SUM(K23:K23)+Q23 -> 306657 | I23: =I22 -> 240000 | J23: 66657 | K23: 0 | L23: 0 | M23: 0 | N23: 0 | O23: 0 | P23: 0 | Q23: 0 | R23: =SUM(S23:AE23) -> 94231 | S23: =FLOOR((G23)*IF(B23<=3,VLOOKUP(A23-1,割合!A:B,2,FALSE),VLOOKUP(A23,割合!A:B,2,FALSE)),1) -> 1226 | T23: =T22 -> 29091 | U23: =U22 -> 7048 | V23: =V22 -> 5176 | W23: 0 | X23: 7060 | Y23: =Y22 -> 11300 | Z23: =Z22 -> 2980 | AA23: =AA22 -> 100 | AB23: =AB22 -> 1580 | AC23: 0 | AD23: =AD22 -> 28670 | AE23: 0
A24: =A12+1 -> 2017 | B24: =B12 -> 2 | C24: =D24+E24 -> 232661 | D24: =F24-R24 -> 232661 | F24: =SUM(I24:P24) -> 327726 | G24: =SUM(I24:O24)-N24-M24 -> 327726 | H24: =SUM(I24:O24)-SUM(K24:K24)+Q24 -> 327726 | I24: =I23 -> 240000 | J24: 87726 | K24: 0 | L24: 0 | M24: 0 | N24: 0 | O24: 0 | P24: 0 | Q24: 0 | R24: =SUM(S24:AE24) -> 95065 | S24: =FLOOR((G24)*IF(B24<=3,VLOOKUP(A24-1,割合!A:B,2,FALSE),VLOOKUP(A24,割合!A:B,2,FALSE)),1) -> 1310 | T24: =T23 -> 29091 | U24: =U23 -> 7048 | V24: =V23 -> 5176 | W24: 0 | X24: 7810 | Y24: =Y23 -> 11300 | Z24: =Z23 -> 2980 | AA24: =AA23 -> 100 | AB24: =AB23 -> 1580 | AC24: 0 | AD24: =AD23 -> 28670 | AE24: 0
A25: =A13+1 -> 2017 | B25: =B13 -> 3 | C25: =D25+E25 -> 226392 | D25: =F25-R25 -> 226392 | F25: =SUM(I25:P25) -> 321191 | G25: =SUM(I25:O25)-N25-M25 -> 321191 | H25: =SUM(I25:O25)-SUM(K25:K25)+Q25 -> 321191 | I25: =I24 -> 240000 | J25: 81191 | K25: 0 | L25: 0 | M25: 0 | N25: 0 | O25: 0 | P25: 0 | Q25: 0 | R25: =SUM(S25:AE25) -> 94799 | S25: =FLOOR((G25)*IF(B25<=3,VLOOKUP(A25-1,割合!A:B,2,FALSE),VLOOKUP(A25,割合!A:B,2,FALSE)),1) -> 1284 | T25: =T24 -> 29091 | U25: =U24 -> 7048 | V25: =V24 -> 5176 | W25: 0 | X25: 7570 | Y25: =Y24 -> 11300 | Z25: =Z24 -> 2980 | AA25: =AA24 -> 100 | AB25: =AB24 -> 1580 | AC25: 0 | AD25: =AD24 -> 28670 | AE25: 0
A26: =A14+1 -> 2017 | B26: =B14 -> 4 | C26: =D26+E26 -> 469725 | D26: =F26-R26 -> 469725 | F26: =SUM(I26:P26) -> 566399 | G26: =SUM(I26:O26)-N26-M26 -> 566399 | H26: =SUM(I26:O26)-SUM(K26:K26)+Q26 -> 349989 | I26: 246900 | J26: 103089 | K26: 216410 | L26: 0 | M26: 0 | N26: 0 | O26: 0 | P26: 0 | Q26: 0 | R26: =SUM(S26:AE26) -> 96674 | S26: =FLOOR((G26)*IF(B26<=3,VLOOKUP(A26-1,割合!A:B,2,FALSE),VLOOKUP(A26,割合!A:B,2,FALSE)),1) -> 1699 | T26: =T25 -> 29091 | U26: 7264 | V26: 4960 | W26: 0 | X26: 8950 | Y26: =Y25 -> 11300 | Z26: 3060 | AA26: =AA25 -> 100 | AB26: =AB25 -> 1580 | AC26: 0 | AD26: =AD25 -> 28670 | AE26: 0
A27: =A15+1 -> 2017 | B27: =B15 -> 5 | C27: =D27+E27 -> 273598 | D27: =F27-R27 -> 273598 | F27: =SUM(I27:P27) -> 371413 | G27: =SUM(I27:O27)-N27-M27 -> 363413 | H27: =SUM(I27:O27)-SUM(K27:K27)+Q27 -> 371413 | I27: =I26 -> 246900 | J27: 116513 | K27: 0 | L27: 0 | M27: 0 | N27: 8000 | O27: 0 | P27: 0 | Q27: 0 | R27: =SUM(S27:AE27) -> 97815 | S27: =FLOOR((G27)*IF(B27<=3,VLOOKUP(A27-1,割合!A:B,2,FALSE),VLOOKUP(A27,割合!A:B,2,FALSE)),1) -> 1090 | T27: =T26 -> 29091 | U27: =U26 -> 7264 | V27: =V26 -> 4960 | W27: 0 | X27: 10750 | Y27: =Y26 -> 11300 | Z27: =Z26 -> 3060 | AA27: 50 | AB27: =AB26 -> 1580 | AC27: 0 | AD27: =AD26 -> 28670 | AE27: 0
A28: =A16+1 -> 2017 | B28: =B16 -> 6 | C28: =D28+E28 -> 565961 | D28: =F28-R28 -> 175429 | E28: =AF28-AJ28 -> 390532 | F28: =SUM(I28:P28) -> 279853 | G28: =SUM(I28:O28)-N28-M28 -> 279853 | H28: =SUM(I28:O28)-SUM(K28:K28)+Q28 -> 279853 | I28: =I27 -> 246900 | J28: 32953 | K28: 0 | L28: 0 | M28: 0 | N28: 0 | O28: 0 | P28: 0 | Q28: 0 | R28: =SUM(S28:AE28) -> 104424 | S28: =FLOOR((G28)*IF(B28<=3,VLOOKUP(A28-1,割合!A:B,2,FALSE),VLOOKUP(A28,割合!A:B,2,FALSE)),1) -> 839 | T28: =T27 -> 29091 | U28: =U27 -> 7264 | V28: =V27 -> 4960 | W28: 0 | X28: 6110 | Y28: 22800 | Z28: =Z27 -> 3060 | AA28: =AA27 -> 50 | AB28: =AB27 -> 1580 | AC28: 0 | AD28: =AD27 -> 28670 | AE28: 0 | AF28: =SUM(AG28:AI28) -> 490000 | AG28: 250000 | AH28: 240000 | AJ28: =SUM(AK28:AP28) -> 99468 | AK28: =FLOOR(AF28*VLOOKUP(A28,割合!A:B,2,FALSE),1) -> 1470 | AL28: 44545 | AM28: 11122 | AN28: 7596 | AO28: 0 | AP28: 34735
A29: =A17+1 -> 2017 | B29: =B17 -> 7 | C29: =D29+E29 -> 177434 | D29: =F29-R29 -> 177434 | F29: =SUM(I29:P29) -> 281212 | G29: =SUM(I29:O29)-N29-M29 -> 281212 | H29: =SUM(I29:O29)-SUM(K29:K29)+Q29 -> 281212 | I29: =I28 -> 246900 | J29: 34312 | K29: 0 | L29: 0 | M29: 0 | N29: 0 | O29: 0 | P29: 0 | Q29: 0 | R29: =SUM(S29:AE29) -> 103778 | S29: =FLOOR((G29)*IF(B29<=3,VLOOKUP(A29-1,割合!A:B,2,FALSE),VLOOKUP(A29,割合!A:B,2,FALSE)),1) -> 843 | T29: =T28 -> 29091 | U29: =U28 -> 7264 | V29: =V28 -> 4960 | W29: 0 | X29: 6160 | Y29: 22100 | Z29: =Z28 -> 3060 | AA29: =AA28 -> 50 | AB29: =AB28 -> 1580 | AC29: 0 | AD29: =AD28 -> 28670 | AE29: 0
A30: =A18+1 -> 2017 | B30: =B18 -> 8 | C30: =D30+E30 -> 155457 | D30: =F30-R30 -> 155457 | F30: =SUM(I30:P30) -> 263536 | G30: =SUM(I30:O30)-N30-M30 -> 263536 | H30: =SUM(I30:O30)-SUM(K30:K30)+Q30 -> 263536 | I30: =I29 -> 246900 | J30: 16636 | K30: 0 | L30: 0 | M30: 0 | N30: 0 | O30: 0 | P30: 0 | Q30: 0 | R30: =SUM(S30:AE30) -> 108079 | S30: =FLOOR((G30)*IF(B30<=3,VLOOKUP(A30-1,割合!A:B,2,FALSE),VLOOKUP(A30,割合!A:B,2,FALSE)),1) -> 790 | T30: 32727 | U30: 8171 | V30: 5581 | W30: 0 | X30: 5350 | Y30: =Y29 -> 22100 | Z30: =Z29 -> 3060 | AA30: =AA29 -> 50 | AB30: =AB29 -> 1580 | AC30: 0 | AD30: =AD29 -> 28670 | AE30: 0
A31: =A19+1 -> 2017 | B31: =B19 -> 9 | C31: =D31+E31 -> 163675 | D31: =F31-R31 -> 163675 | F31: =SUM(I31:P31) -> 272095 | G31: =SUM(I31:O31)-N31-M31 -> 277053 | H31: =SUM(I31:O31)-SUM(K31:K31)+Q31 -> 272095 | I31: =I30 -> 246900 | J31: 30153 | K31: 0 | L31: 0 | M31: 0 | N31: -4958 | O31: 0 | P31: 0 | Q31: 0 | R31: =SUM(S31:AE31) -> 108420 | S31: =FLOOR((G31)*IF(B31<=3,VLOOKUP(A31-1,割合!A:B,2,FALSE),VLOOKUP(A31,割合!A:B,2,FALSE)),1) -> 831 | T31: =T30 -> 32727 | U31: =U30 -> 8171 | V31: =V30 -> 5581 | W31: 0 | X31: 5650 | Y31: =Y30 -> 22100 | Z31: =Z30 -> 3060 | AA31: =AA30 -> 50 | AB31: =AB30 -> 1580 | AC31: 0 | AD31: =AD30 -> 28670 | AE31: 0
A32: =A20+1 -> 2017 | B32: =B20 -> 10 | C32: =D32+E32 -> 399184 | D32: =F32-R32 -> 399184 | F32: =SUM(I32:P32) -> 509223 | G32: =SUM(I32:O32)-N32-M32 -> 509223 | H32: =SUM(I32:O32)-SUM(K32:K32)+Q32 -> 292813 | I32: =I31 -> 246900 | J32: 45913 | K32: 216410 | L32: 0 | M32: 0 | N32: 0 | O32: 0 | P32: 0 | Q32: 0 | R32: =SUM(S32:AE32) -> 110039 | S32: =FLOOR((G32)*IF(B32<=3,VLOOKUP(A32-1,割合!A:B,2,FALSE),VLOOKUP(A32,割合!A:B,2,FALSE)),1) -> 1527 | T32: 32940 | U32: =U31 -> 8171 | V32: =V31 -> 5581 | W32: 0 | X32: 6360 | Y32: =Y31 -> 22100 | Z32: =Z31 -> 3060 | AA32: =AA31 -> 50 | AB32: =AB31 -> 1580 | AC32: 0 | AD32: =AD31 -> 28670 | AE32: 0
A33: =A21+1 -> 2017 | B33: =B21 -> 11 | C33: =D33+E33 -> 37426 | D33: =F33-R33 -> 37426 | F33: =SUM(I33:P33) -> 147343 | G33: =SUM(I33:O33)-N33-M33 -> 147343 | H33: =SUM(I33:O33)-SUM(K33:K33)+Q33 -> 278093 | I33: =I32 -> 246900 | J33: 31193 | K33: -130750 | L33: 0 | M33: 0 | N33: 0 | O33: 0 | P33: 0 | Q33: 0 | R33: =SUM(S33:AE33) -> 109917 | S33: =FLOOR((G33)*IF(B33<=3,VLOOKUP(A33-1,割合!A:B,2,FALSE),VLOOKUP(A33,割合!A:B,2,FALSE)),1) -> 442 | T33: =T32 -> 32940 | U33: =U32 -> 8171 | V33: =V32 -> 5581 | W33: 0 | X33: 6660 | Y33: =Y32 -> 22100 | Z33: =Z32 -> 3060 | AA33: =AA32 -> 50 | AB33: =AB32 -> 1580 | AC33: 663 | AD33: =AD32 -> 28670 | AE33: 0
A34: =A22+1 -> 2017 | B34: =B22 -> 12 | C34: =D34+E34 -> 588350 | D34: =F34-R34 -> 167423 | E34: =AF34-AJ34 -> 420927 | F34: =SUM(I34:P34) -> 299410 | G34: =SUM(I34:O34)-N34-M34 -> 299410 | H34: =SUM(I34:O34)-SUM(K34:K34)+Q34 -> 299410 | I34: =I33 -> 246900 | J34: 52510 | K34: 0 | L34: 0 | M34: 0 | N34: 0 | O34: 0 | P34: 0 | Q34: 0 | R34: =SUM(S34:AE34) -> 131987 | S34: =FLOOR((G34)*IF(B34<=3,VLOOKUP(A34-1,割合!A:B,2,FALSE),VLOOKUP(A34,割合!A:B,2,FALSE)),1) -> 898 | T34: =T33 -> 32940 | U34: =U33 -> 8171 | V34: =V33 -> 5581 | W34: 0 | X34: -27633 | Y34: =Y33 -> 22100 | Z34: =Z33 -> 3060 | AA34: =AA33 -> 50 | AB34: =AB33 -> 1580 | AC34: 0 | AD34: 45370 | AE34: 39870 | AF34: =SUM(AG34:AI34) -> 517000 | AG34: 280000 | AH34: 237000 | AJ34: =SUM(AK34:AP34) -> 96073 | AK34: =FLOOR(AF34*VLOOKUP(A34,割合!A:B,2,FALSE),1) -> 1551 | AL34: 47305 | AM34: 11734 | AN34: 8015 | AO34: 0 | AP34: 27468 | AQ34: =SUM(H23:H34)+SUM(AF23:AF34) -> 4650988 | AR34: =AQ34-AQ22 -> -458231 | AS34: =AR34/12 -> -38185.917 | AT34: =SUM(C23:C34)+SUM(AC23:AE34) -> 3903562 | AU34: =AT34-AT22 -> -592294 | AV34: =AU34/12 -> -49357.833 | AW34: =AT34/AQ34 -> 0.83929737
A35: =A23+1 -> 2018 | B35: =B23 -> 1 | C35: =D35+E35 -> 178822 | D35: =F35-R35 -> 178822 | F35: =SUM(I35:P35) -> 305530 | G35: =SUM(I35:O35)-N35-M35 -> 305530 | H35: =SUM(I35:O35)-SUM(K35:K35)+Q35 -> 305530 | I35: =I34 -> 246900 | J35: 58630 | K35: 0 | L35: 0 | M35: 0 | N35: 0 | O35: 0 | P35: 0 | Q35: 0 | R35: =SUM(S35:AE35) -> 126708 | S35: =FLOOR((G35)*IF(B35<=3,VLOOKUP(A35-1,割合!A:B,2,FALSE),VLOOKUP(A35,割合!A:B,2,FALSE)),1) -> 916 | T35: =T34 -> 32940 | U35: =U34 -> 8171 | V35: =V34 -> 5581 | W35: 0 | X35: 6830 | Y35: =Y34 -> 22100 | Z35: =Z34 -> 3060 | AA35: =AA34 -> 50 | AB35: 1690 | AC35: 0 | AD35: =AD34 -> 45370 | AE35: 0
A36: =A24+1 -> 2018 | B36: =B24 -> 2 | C36: =D36+E36 -> 195377 | D36: =F36-R36 -> 195377 | F36: =SUM(I36:P36) -> 325515 | G36: =SUM(I36:O36)-N36-M36 -> 325515 | H36: =SUM(I36:O36)-SUM(K36:K36)+Q36 -> 325515 | I36: =I35 -> 246900 | J36: 78615 | K36: 0 | L36: 0 | M36: 0 | N36: 0 | O36: 0 | P36: 0 | Q36: 0 | R36: =SUM(S36:AE36) -> 130138 | S36: =FLOOR((G36)*IF(B36<=3,VLOOKUP(A36-1,割合!A:B,2,FALSE),VLOOKUP(A36,割合!A:B,2,FALSE)),1) -> 976 | T36: =T35 -> 32940 | U36: =U35 -> 8171 | V36: =V35 -> 5581 | W36: 0 | X36: 7550 | Y36: =Y35 -> 22100 | Z36: =Z35 -> 3060 | AA36: =AA35 -> 50 | AB36: =AB35 -> 1690 | AC36: 2650 | AD36: =AD35 -> 45370 | AE36: 0
A37: =A25+1 -> 2018 | B37: =B25 -> 3 | C37: =D37+E37 -> 193056 | D37: =F37-R37 -> 193056 | F37: =SUM(I37:P37) -> 327363 | G37: =SUM(I37:O37)-N37-M37 -> 327363 | H37: =SUM(I37:O37)-SUM(K37:K37)+Q37 -> 327363 | I37: =I36 -> 246900 | J37: 80463 | K37: 0 | L37: 0 | M37: 0 | N37: 0 | O37: 0 | P37: 0 | Q37: 0 | R37: =SUM(S37:AE37) -> 134307 | S37: =FLOOR((G37)*IF(B37<=3,VLOOKUP(A37-1,割合!A:B,2,FALSE),VLOOKUP(A37,割合!A:B,2,FALSE)),1) -> 982 | T37: =T36 -> 32940 | U37: =U36 -> 8171 | V37: =V36 -> 5581 | W37: 0 | X37: 7610 | Y37: =Y36 -> 22100 | Z37: =Z36 -> 3060 | AA37: =AA36 -> 50 | AB37: =AB36 -> 1690 | AC37: 6753 | AD37: =AD36 -> 45370 | AE37: 0
A38: =A26+1 -> 2018 | B38: =B26 -> 4 | C38: =D38+E38 -> 191807 | D38: =F38-R38 -> 191807 | F38: =SUM(I38:P38) -> 328632 | G38: =SUM(I38:O38)-N38-M38 -> 328632 | H38: =SUM(I38:O38)-SUM(K38:K38)+Q38 -> 328632 | I38: 252130 | J38: 76502 | K38: 0 | L38: 0 | M38: 0 | N38: 0 | O38: 0 | P38: 0 | Q38: 0 | R38: =SUM(S38:AE38) -> 136825 | S38: =FLOOR((G38)*IF(B38<=3,VLOOKUP(A38-1,割合!A:B,2,FALSE),VLOOKUP(A38,割合!A:B,2,FALSE)),1) -> 985 | T38: =T37 -> 32940 | U38: 8208 | V38: 5544 | W38: 0 | X38: 7660 | Y38: =Y37 -> 22100 | Z38: 3120 | AA38: =AA37 -> 50 | AB38: =AB37 -> 1690 | AC38: 9158 | AD38: =AD37 -> 45370 | AE38: 0
A39: =A27+1 -> 2018 | B39: =B27 -> 5 | C39: =D39+E39 -> 242455 | D39: =F39-R39 -> 242455 | F39: =SUM(I39:P39) -> 379732 | G39: =SUM(I39:O39)-N39-M39 -> 379732 | H39: =SUM(I39:O39)-SUM(K39:K39)+Q39 -> 294072 | I39: =I38 -> 252130 | J39: 41942 | K39: 85660 | L39: 0 | M39: 0 | N39: 0 | O39: 0 | P39: 0 | Q39: 0 | R39: =SUM(S39:AE39) -> 137277 | S39: =FLOOR((G39)*IF(B39<=3,VLOOKUP(A39-1,割合!A:B,2,FALSE),VLOOKUP(A39,割合!A:B,2,FALSE)),1) -> 1139 | T39: =T38 -> 32940 | U39: =U38 -> 8208 | V39: =V38 -> 5544 | W39: 0 | X39: 6420 | Y39: =Y38 -> 22100 | Z39: =Z38 -> 3120 | AA39: =AA38 -> 50 | AB39: =AB38 -> 1690 | AC39: 10696 | AD39: =AD38 -> 45370 | AE39: 0
A40: =A28+1 -> 2018 | B40: =B28 -> 6 | C40: =D40+E40 -> 678450 | D40: =F40-R40 -> 165179 | E40: =AF40-AJ40 -> 513271 | F40: =SUM(I40:P40) -> 296072 | G40: =SUM(I40:O40)-N40-M40 -> 296072 | H40: =SUM(I40:O40)-SUM(K40:K40)+Q40 -> 296072 | I40: =I39 -> 252130 | J40: 43942 | K40: 0 | L40: 0 | M40: 0 | N40: 0 | O40: 0 | P40: 0 | Q40: 0 | R40: =SUM(S40:AE40) -> 130893 | S40: =FLOOR((G40)*IF(B40<=3,VLOOKUP(A40-1,割合!A:B,2,FALSE),VLOOKUP(A40,割合!A:B,2,FALSE)),1) -> 888 | T40: =T39 -> 32940 | U40: =U39 -> 8208 | V40: =V39 -> 5544 | W40: 0 | X40: 6500 | Y40: 18200 | Z40: =Z39 -> 3120 | AA40: =AA39 -> 50 | AB40: =AB39 -> 1690 | AC40: 8383 | AD40: =AD39 -> 45370 | AE40: 0 | AF40: =SUM(AG40:AI40) -> 617000 | AG40: 280000 | AH40: 272000 | AI40: 65000 | AJ40: =SUM(AK40:AP40) -> 103729 | AK40: =FLOOR(AF40*VLOOKUP(A40,割合!A:B,2,FALSE),1) -> 1851 | AL40: 56455 | AM40: 14068 | AN40: 9501 | AO40: 0 | AP40: 21854
...

Sheet 割合
B1: 雇用保険料
A2: 2015 | B2: =5/1000 -> 0.005
A3: 2016 | B3: =4/1000 -> 0.004
A4: 2017 | B4: =3/1000 -> 0.003
A5: 2018 | B5: =3/1000 -> 0.003
A6: 2019 | B6: =3/1000 -> 0.003
A7: 2020 | B7: =3/1000 -> 0.003
A8: 2021 | B8: =3/1000 -> 0.003
A9: 2022 | B9: =3/1000 -> 0.003
A10: 2023 | B10: =6/1000 -> 0.006
A11: 2024 | B11: =6/1000 -> 0.006
A12: 2025 | B12: =5.5/1000 -> 0.0055
A13: 2026 | B13: =5/1000 -> 0.005

Sheet 基本給
A1: 基本給
A2: 2015年 | B2: 233000 | E2: 25歳
A3: 2016年 | B3: 240000 | C3: =B3-B2 -> 7000 | D3: =C3/B2 -> 0.030042918 | E3: 26歳
A4: 2017年 | B4: 246900 | C4: =B4-B3 -> 6900 | D4: =C4/B3 -> 0.02875 | E4: 27歳
A5: 2018年 | B5: 252130 | C5: =B5-B4 -> 5230 | D5: =C5/B4 -> 0.021182665 | E5: 28歳
A6: 2019年 | B6: 261530 | C6: =B6-B5 -> 9400 | D6: =C6/B5 -> 0.037282354 | E6: 29歳
A7: 2020年 | B7: 268230 | C7: =B7-B6 -> 6700 | D7: =C7/B6 -> 0.025618476 | E7: 30歳
A8: 2021年 | B8: 290000 | C8: =B8-B7 -> 21770 | D8: =C8/B7 -> 0.08116169 | E8: 31歳
A9: 2022年 | B9: 300500 | C9: =B9-B8 -> 10500 | D9: =C9/B8 -> 0.036206897 | E9: 32歳
A10: 2023年 | B10: 314400 | C10: =B10-B9 -> 13900 | D10: =C10/B9 -> 0.04625624 | E10: 33歳
A11: 2024年 | B11: 335600 | C11: =B11-B10 -> 21200 | D11: =C11/B10 -> 0.067430025 | E11: 34歳
A12: 2025年 | B12: 385500 | C12: =B12-B11 -> 49900 | D12: =C12/B11 -> 0.14868892 | E12: 35歳
A13: 2025年 | B13: 400700 | C13: =B13-B12 -> 15200 | D13: =C13/B12 -> 0.039429313 | E13: 35歳
A15: 2026年 | B15: =B13+C15 -> 415639.04 | C15: =B13*D15 -> 14939.039 | D15: =MEDIAN(D3:D13) -> 0.037282354 | E15: 36歳
A16: 2027年 | B16: =B15+C16 -> 431135.04 | C16: =B15*D16 -> 15496.002 | D16: =D15 -> 0.037282354 | E16: 37歳
A17: 2028年 | B17: =B16+C17 -> 447208.77 | C17: =B16*D17 -> 16073.729 | D17: =D16 -> 0.037282354 | E17: 38歳
A18: 2029年 | B18: =B17+C18 -> 463881.77 | C18: =B17*D18 -> 16672.996 | D18: =D17 -> 0.037282354 | E18: 39歳
A19: 2030年 | B19: =B18+C19 -> 481176.37 | C19: =B18*D19 -> 17294.604 | D19: =D18 -> 0.037282354 | E19: 40歳
A20: 2031年 | B20: =B19+C20 -> 499115.76 | C20: =B19*D20 -> 17939.388 | D20: =D19 -> 0.037282354 | E20: 41歳
A21: 2032年 | B21: =B20+C21 -> 517723.97 | C21: =B20*D21 -> 18608.211 | D21: =D20 -> 0.037282354 | E21: 42歳
A22: 2033年 | B22: =B21+C22 -> 537025.94 | C22: =B21*D22 -> 19301.968 | D22: =D21 -> 0.037282354 | E22: 43歳
A23: 2034年 | B23: =B22+C23 -> 557047.53 | C23: =B22*D23 -> 20021.591 | D23: =D22 -> 0.037282354 | E23: 44歳
A24: 2035年 | B24: =B23+C24 -> 577815.57 | C24: =B23*D24 -> 20768.043 | D24: =D23 -> 0.037282354 | E24: 45歳
A25: 2036年 | B25: =B24+C25 -> 599357.9 | C25: =B24*D25 -> 21542.325 | D25: =D24 -> 0.037282354 | E25: 46歳
A26: 2037年 | B26: =B25+C26 -> 621703.37 | C26: =B25*D26 -> 22345.474 | D26: =D25 -> 0.037282354 | E26: 47歳
A27: 2038年 | B27: =B26+C27 -> 644881.94 | C27: =B26*D27 -> 23178.565 | D27: =D26 -> 0.037282354 | E27: 48歳
... A44: 2055年 | B44: =B43+C44 -> 1201514.6 | C44: =B43*D44 -> 43185.244 | D44: =D43 -> 0.037282354 | E44: 65歳

Sheet 在宅勤務費用補填
A2: 2021 | B2: 4 | C2: 20 | D2: =給料!M74 -> 0 | G2: =E2*F2 -> 0
A3: 2021 | B3: 5 | C3: 19 | D3: =給料!M75 -> 0 | E3: =IF(D2=0,C2+E2,C2) -> 20 | F3: =IF(D3=0,F2,D3/E3) -> 0 | G3: =E3*F3 -> 0
A4: 2021 | B4: 6 | C4: 24 | D4: =給料!M76 -> 0 | E4: =IF(D3=0,C3+E3,C3) -> 39 | F4: =IF(D4=0,F3,D4/E4) -> 0 | G4: =E4*F4 -> 0
A5: 2021 | B5: 7 | C5: 0 | D5: =給料!M77 -> 0 | E5: =IF(D4=0,C4+E4,C4) -> 63 | F5: =IF(D5=0,F4,D5/E5) -> 0 | G5: =E5*F5 -> 0
A6: 2021 | B6: 8 | C6: 18 | D6: =給料!M78 -> 6300 | E6: =IF(D5=0,C5+E5,C5) -> 63 | F6: =IF(D6=0,F5,D6/E6) -> 100 | G6: =E6*F6 -> 6300
A7: 2021 | B7: 9 | C7: 23 | D7: =給料!M79 -> 1800 | E7: =IF(D6=0,C6+E6,C6) -> 18 | F7: =IF(D7=0,F6,D7/E7) -> 100 | G7: =E7*F7 -> 1800
A8: 2021 | B8: 10 | C8: 22 | D8: =給料!M80 -> 2300 | E8: =IF(D7=0,C7+E7,C7) -> 23 | F8: =IF(D8=0,F7,D8/E8) -> 100 | G8: =E8*F8 -> 2300
A9: 2021 | B9: 11 | C9: 23 | D9: =給料!M81 -> 2200 | E9: =IF(D8=0,C8+E8,C8) -> 22 | F9: =IF(D9=0,F8,D9/E9) -> 100 | G9: =E9*F9 -> 2200
A10: 2021 | B10: 12 | C10: 23 | D10: =給料!M82 -> 2300 | E10: =IF(D9=0,C9+E9,C9) -> 23 | F10: =IF(D10=0,F9,D10/E10) -> 100 | G10: =E10*F10 -> 2300
A11: 2022 | B11: 1 | C11: 22 | D11: =給料!M83 -> 2300 | E11: =IF(D10=0,C10+E10,C10) -> 23 | F11: =IF(D11=0,F10,D11/E11) -> 100 | G11: =E11*F11 -> 2300
A12: 2022 | B12: 2 | C12: 16 | D12: =給料!M84 -> 0 | E12: =IF(D11=0,C11+E11,C11) -> 22 | F12: =IF(D12=0,F11,D12/E12) -> 100 | G12: =E12*F12 -> 2200
A13: 2022 | B13: 3 | C13: 24 | D13: =給料!M85 -> 3800 | E13: =IF(D12=0,C12+E12,C12) -> 38 | F13: =IF(D13=0,F12,D13/E13) -> 100 | G13: =E13*F13 -> 3800
A14: =A2+1 -> 2022 | B14: =B2 -> 4 | C14: 20 | D14: =給料!M86 -> 2400 | E14: =IF(D13=0,C13+E13,C13) -> 24 | F14: =IF(D14=0,F13,D14/E14) -> 100 | G14: =E14*F14 -> 2400
A15: =A3+1 -> 2022 | B15: =B3 -> 5 | C15: 19 | D15: =給料!M87 -> 2000 | E15: =IF(D14=0,C14+E14,C14) -> 20 | F15: =IF(D15=0,F14,D15/E15) -> 100 | G15: =E15*F15 -> 2000
A16: =A4+1 -> 2022 | B16: =B4 -> 6 | C16: 25 | D16: =給料!M88 -> 1900 | E16: =IF(D15=0,C15+E15,C15) -> 19 | F16: =IF(D16=0,F15,D16/E16) -> 100 | G16: =E16*F16 -> 1900
A17: =A5+1 -> 2022 | B17: =B5 -> 7 | C17: 22 | D17: =給料!M89 -> 2500 | E17: =IF(D16=0,C16+E16,C16) -> 25 | F17: =IF(D17=0,F16,D17/E17) -> 100 | G17: =E17*F17 -> 2500
A18: =A6+1 -> 2022 | B18: =B6 -> 8 | C18: 26 | D18: =給料!M90 -> 0 | E18: =IF(D17=0,C17+E17,C17) -> 22 | F18: =IF(D18=0,F17,D18/E18) -> 100 | G18: =E18*F18 -> 2200
A19: =A7+1 -> 2022 | B19: =B7 -> 9 | C19: 19 | D19: =給料!M91 -> 4800 | E19: =IF(D18=0,C18+E18,C18) -> 48 | F19: =IF(D19=0,F18,D19/E19) -> 100 | G19: =E19*F19 -> 4800
A20: =A8+1 -> 2022 | B20: =B8 -> 10 | C20: 20 | D20: =給料!M92 -> 0 | E20: =IF(D19=0,C19+E19,C19) -> 19 | F20: =IF(D20=0,F19,D20/E20) -> 100 | G20: =E20*F20 -> 1900
A21: =A9+1 -> 2022 | B21: =B9 -> 11 | C21: 24 | D21: =給料!M93 -> 3900 | E21: =IF(D20=0,C20+E20,C20) -> 39 | F21: =IF(D21=0,F20,D21/E21) -> 100 | G21: =E21*F21 -> 3900
A22: =A10+1 -> 2022 | B22: =B10 -> 12 | C22: 23 | D22: =給料!M94 -> 0 | E22: =IF(D21=0,C21+E21,C21) -> 24 | F22: =IF(D22=0,F21,D22/E22) -> 100 | G22: =E22*F22 -> 2400
A23: =A11+1 -> 2023 | B23: =B11 -> 1 | C23: 23 | D23: =給料!M95 -> 4700 | E23: =IF(D22=0,C22+E22,C22) -> 47 | F23: =IF(D23=0,F22,D23/E23) -> 100 | G23: =E23*F23 -> 4700
A24: =A12+1 -> 2023 | B24: =B12 -> 2 | C24: 23 | D24: =給料!M96 -> 2300 | E24: =IF(D23=0,C23+E23,C23) -> 23 | F24: =IF(D24=0,F23,D24/E24) -> 100 | G24: =E24*F24 -> 2300
A25: =A13+1 -> 2023 | B25: =B13 -> 3 | C25: 24 | D25: =給料!M97 -> 2300 | E25: =IF(D24=0,C24+E24,C24) -> 23 | F25: =IF(D25=0,F24,D25/E25) -> 100 | G25: =E25*F25 -> 2300
... A28: =A16+1 -> 2023 | B28: =B16 -> 6 | C28: 23 | D28: =給料!M100 -> 0 | E28: =IF(D27=0,C27+E27,C27) -> 18 | F28: =IF(D28=0,F27,D28/E28) -> 140 | G28: =E28*F28 -> 2520
A29: =A17+1 -> 2023 | B29: =B17 -> 7 | C29: 22 | D29: =給料!M101 -> 2520 | E29: =C27 -> 18 | F29: =IF(D29=0,F28,D29/E29) -> 140 | G29: =E29*F29 -> 2520
A30: =A18+1 -> 2023 | B30: =B18 -> 8 | C30: 25 | D30: =給料!M102 -> 6300 | E30: =C28+C29 -> 45 | F30: =IF(D30=0,F29,D30/E30) -> 140 | G30: =E30*F30 -> 6300
A31: =A19+1 -> 2023 | B31: =B19 -> 9 | C31: 22 | D31: =給料!M103 -> 3500 | E31: =IF(D30=0,C30+E30,C30) -> 25 | F31: =IF(D31=0,F30,D31/E31) -> 140 | G31: =E31*F31 -> 3500
A32: =A20+1 -> 2023 | B32: =B20 -> 10 | C32: 20 | D32: =給料!M104 -> 3080 | E32: =IF(D31=0,C31+E31,C31) -> 22 | F32: =IF(D32=0,F31,D32/E32) -> 140 | G32: =E32*F32 -> 3080
A33: =A21+1 -> 2023 | B33: =B21 -> 11 | C33: 22 | D33: =給料!M105 -> 2800 | E33: =IF(D32=0,C32+E32,C32) -> 20 | F33: =IF(D33=0,F32,D33/E33) -> 140 | G33: =E33*F33 -> 2800
A34: =A22+1 -> 2023 | B34: =B22 -> 12 | C34: 22 | D34: =給料!M106 -> 3080 | E34: =IF(D33=0,C33+E33,C33) -> 22 | F34: =IF(D34=0,F33,D34/E34) -> 140 | G34: =E34*F34 -> 3080
A35: =A23+1 -> 2024 | B35: =B23 -> 1 | C35: 21 | D35: =給料!M107 -> 3080 | E35: =IF(D34=0,C34+E34,C34) -> 22 | F35: =IF(D35=0,F34,D35/E35) -> 140 | G35: =E35*F35 -> 3080
A36: =A24+1 -> 2024 | B36: =B24 -> 2 | C36: 23 | D36: =給料!M108 -> 2940 | E36: =IF(D35=0,C35+E35,C35) -> 21 | F36: =IF(D36=0,F35,D36/E36) -> 140 | G36: =E36*F36 -> 2940
A37: =A25+1 -> 2024 | B37: =B25 -> 3 | C37: 21 | D37: =給料!M109 -> 3220 | E37: =IF(D36=0,C36+E36,C36) -> 23 | F37: =IF(D37=0,F36,D37/E37) -> 140 | G37: =E37*F37 -> 3220
A38: =A26+1 -> 2024 | B38: =B26 -> 4 | C38: 22 | D38: =給料!M110 -> 0 | E38: =IF(D37=0,C37+E37,C37) -> 21 | F38: =IF(D38=0,F37,D38/E38) -> 140 | G38: =E38*F38 -> 2940
A39: =A27+1 -> 2024 | B39: =B27 -> 5 | C39: 21 | D39: =給料!M111 -> 6020 | E39: =IF(D38=0,C38+E38,C38) -> 43 | F39: =IF(D39=0,F38,D39/E39) -> 140 | G39: =E39*F39 -> 6020
A40: =A28+1 -> 2024 | B40: =B28 -> 6 | C40: 18 | D40: =給料!M112 -> 2940 | E40: =IF(D39=0,C39+E39,C39) -> 21 | F40: =IF(D40=0,F39,D40/E40) -> 140 | G40: =E40*F40 -> 2940
A41: =A29+1 -> 2024 | B41: =B29 -> 7 | C41: 22 | D41: =給料!M113 -> 2520 | E41: =IF(D40=0,C40+E40,C40) -> 18 | F41: =IF(D41=0,F40,D41/E41) -> 140 | G41: =E41*F41 -> 2520
A42: =A30+1 -> 2024 | B42: =B30 -> 8 | C42: 22 | D42: =給料!M114 -> 3080 | E42: =IF(D41=0,C41+E41,C41) -> 22 | F42: =IF(D42=0,F41,D42/E42) -> 140 | G42: =E42*F42 -> 3080
... A50: =A38+1 -> 2025 | B50: =B38 -> 4 | C50: 20 | D50: =給料!M122 -> 0 | E50: =IF(D49=0,C49+E49,C49) -> 22 | F50: =IF(D50=0,F49,D50/E50) -> 150 | G50: =E50*F50 -> 3300
...

Sheet 出張
E1: 金額 | F1: 支払金額 | G1: 電車 | H1: 移動日当 | I1: 宿泊日当 | J1: 新幹線 | K1: 宿泊
A2: 44862 | B2: 出張 | C2: 静岡 | D2: 名古屋 | E2: =SUM(G2:K2) -> 14689 | F2: =SUM(G2:K2)-J2-K2 -> 2800 | G2: =150+150 -> 300 | H2: 2500 | I2: 0 | J2: =5949+5940 -> 11889 | K2: 0
A3: 44875 | B3: 通勤 | C3: 静岡 | E3: =SUM(G3:K3) -> 300 | F3: =SUM(G3:K3)-J3-K3 -> 300 | G3: =150+150 -> 300 | H3: 0 | I3: 0 | J3: 0 | K3: 0
A4: 44914 | B4: 出張 | C4: 静岡 | D4: 広島 | E4: =SUM(G4:K4) -> 26080 | F4: =SUM(G4:K4)-J4-K4 -> 3950 | G4: 150 | H4: 1000 | I4: 2800 | J4: 15330 | K4: 6800
A5: 44915 | B5: 出張 | C5: 静岡 | D5: 広島 | E5: =SUM(G5:K5) -> 16480 | F5: =SUM(G5:K5)-J5-K5 -> 1150 | G5: 150 | H5: =1000 -> 1000 | I5: 0 | J5: 15330 | K5: 0
A6: 44918 | B6: 出張 | C6: 静岡 | D6: 名古屋 | E6: =SUM(G6:K6) -> 14680 | F6: =SUM(G6:K6)-J6-K6 -> 2800 | G6: =150+150 -> 300 | H6: 2500 | I6: 0 | J6: =5940+5940 -> 11880 | K6: 0
A7: 44923 | B7: 通勤 | C7: 静岡 | E7: =SUM(G7:K7) -> 300 | F7: =SUM(G7:K7)-J7-K7 -> 300 | G7: =150+150 -> 300 | H7: 0 | I7: 0 | J7: 0 | K7: 0
A8: 44979 | B8: 出張 | C8: 静岡 | D8: 玉川事業場 | E8: =SUM(G8:K8) -> 14616 | F8: =SUM(G8:K8)-J8-K8 -> 3136 | G8: =150+168+168+150 -> 636 | H8: 2500 | I8: 0 | J8: =5740+5740 -> 11480 | K8: 0
A9: 45002 | B9: 出張 | C9: 静岡 | D9: 名古屋 | E9: =SUM(G9:K9) -> 16600 | F9: =SUM(G9:K9)-J9-K9 -> 4720 | G9: =1110+1110 -> 2220 | H9: 2500 | I9: 0 | J9: =5940+5940 -> 11880 | K9: 0
A10: 45014 | B10: 出張 | C10: 静岡 | D10: 名古屋 | E10: =SUM(G10:K10) -> 16600 | F10: =SUM(G10:K10)-J10-K10 -> 4720 | G10: =1110+1110 -> 2220 | H10: 2500 | I10: 0 | J10: =5940+5940 -> 11880 | K10: 0
A11: 45016 | B11: 通勤 | C11: 静岡 | E11: =SUM(G11:K11) -> 2220 | F11: =SUM(G11:K11)-J11-K11 -> 2220 | G11: =1110+1110 -> 2220 | H11: 0 | I11: 0 | J11: 0 | K11: 0
B12: 出張 | C12: 静岡 | E12: =SUM(G12:K12) -> 0 | F12: =SUM(G12:K12)-J12-K12 -> 0
B13: 出張 | C13: 静岡 | E13: =SUM(G13:K13) -> 0 | F13: =SUM(G13:K13)-J13-K13 -> 0
B14: 出張 | C14: 静岡 | E14: =SUM(G14:K14) -> 0 | F14: =SUM(G14:K14)-J14-K14 -> 0
B15: 出張 | C15: 静岡 | E15: =SUM(G15:K15) -> 0 | F15: =SUM(G15:K15)-J15-K15 -> 0
B16: 出張 | C16: 静岡 | E16: =SUM(G16:K16) -> 0 | F16: =SUM(G16:K16)-J16-K16 -> 0
B17: 出張 | C17: 静岡 | E17: =SUM(G17:K17) -> 0 | F17: =SUM(G17:K17)-J17-K17 -> 0
B18: 出張 | C18: 静岡 | E18: =SUM(G18:K18) -> 0 | F18: =SUM(G18:K18)-J18-K18 -> 0
B19: 出張 | C19: 静岡 | E19: =SUM(G19:K19) -> 0 | F19: =SUM(G19:K19)-J19-K19 -> 0
B20: 出張 | C20: 静岡 | E20: =SUM(G20:K20) -> 0 | F20: =SUM(G20:K20)-J20-K20 -> 0
B21: 出張 | C21: 静岡 | E21: =SUM(G21:K21) -> 0 | F21: =SUM(G21:K21)-J21-K21 -> 0
B22: 出張 | C22: 静岡 | E22: =SUM(G22:K22) -> 0 | F22: =SUM(G22:K22)-J22-K22 -> 0
B23: 出張 | C23: 静岡 | E23: =SUM(G23:K23) -> 0 | F23: =SUM(G23:K23)-J23-K23 -> 0
... B41: 出張 | C41: 静岡 | E41: =SUM(G41:K41) -> 0 | F41: =SUM(G41:K41)-J41-K41 -> 0
